Workbook
Name Slicer_Payment_Status: #N/A

Sheet Pivot Analysis
A3: Row Labels | B3: Count of Booking_ID
A4: RG Greens | B4: 5
A5: RG Heights | B5: 29
A6: RG Residency | B6: 28
A7: Grand Total | B7: 62
A10: Row Labels | B10: Sum of Booking_Amount
A11: Adajan | B11: 169100000
A12: Bopal | B12: 212350000
A13: Vesu | B13: 32650000
A14: Grand Total | B14: 414100000

Sheet Cleaned Data
A1: Booking_ID | B1: Booking_Date | C1: Sales_Executive | D1: Project_Name | E1: Location | F1: Flat_Type | G1: Booking_Amount | H1: Amount_Received | I1: Payment_Status | J1: Possession_Date | K1: Sales_Target | L1: Remarks | M1: Days_Overdue | N1: Project_Manager | O1: Launch_Year | P1: Performance_Rating | R1: Project_Name | S1: Location | T1: Project_Manager | U1: Launch_Year
A2: RG-001 | B2: 45575 | C2: Pooja Desai | D2: RG Residency | E2: Adajan | F2: 2BHK | G2: 5900000 | H2: 0 | I2: Cancelled | J2: 46082 | K2: 8500000 | L2: Builder referral | M2: 0 | N2: Sneha Kapoor | O2: 2021 | P2: N/A | R2: RG Residency | S2: Adajan | T2: Sneha Kapoor | U2: 2021
A3: RG-002 | B3: 45508 | C3: Pooja Desai | D3: RG Residency | E3: Adajan | F3: 2BHK | G3: 4200000 | H3: 4200000 | I3: Confirmed | J3: 45768 | K3: 8500000 | L3: N/A | M3: 0 | N3: Sneha Kapoor | O3: 2021 | P3: Excellent | R3: RG Heights | S3: Bopal | T3: Raj Malhotra | U3: 2022
A4: RG-003 | B4: 45387 | C4: Ravi Patel | D4: RG Heights | E4: Bopal | F4: 1BHK | G4: 3500000 | H4: 900000 | I4: Pending | J4: 46086 | K4: 8000000 | L4: N/A | M4: 724 | N4: Raj Malhotra | O4: 2022 | P4: Below Target | R4: RG Greens | S4: Vesu | T4: Priya Nair | U4: 2023
A5: RG-004 | B5: 45302 | C5: Karan Mehta | D5: RG Residency | E5: Adajan | F5: 2BHK | G5: 5400000 | H5: 5400000 | I5: Confirmed | J5: 46059 | K5: 7000000 | L5: Online inquiry | M5: 0 | N5: Sneha Kapoor | O5: 2021 | P5: Excellent
A6: RG-005 | B6: 45555 | C6: Meena Shah | D6: RG Heights | E6: Bopal | F6: 2BHK | G6: 5150000 | H6: 5150000 | I6: Confirmed | J6: 46319 | K6: 7500000 | L6: N/A | M6: 0 | N6: Raj Malhotra | O6: 2022 | P6: Excellent
A7: RG-006 | B7: 45485 | C7: Pooja Desai | D7: RG Residency | E7: Adajan | F7: 3BHK | G7: 7950000 | H7: 7950000 | I7: Confirmed | J7: 45847 | K7: 8500000 | L7: N/A | M7: 0 | N7: Sneha Kapoor | O7: 2021 | P7: Excellent
A8: RG-007 | B8: 45519 | C8: Amit Verma | D8: RG Residency | E8: Adajan | F8: 2BHK | G8: 4200000 | H8: 4200000 | I8: Confirmed | J8: 46140 | K8: 9000000 | L8: N/A | M8: 0 | N8: Sneha Kapoor | O8: 2021 | P8: Excellent
A9: RG-008 | B9: 45515 | C9: Pooja Desai | D9: RG Heights | E9: Bopal | F9: 2BHK | G9: 4400000 | H9: 1350000 | I9: Pending | J9: 46071 | K9: 8500000 | L9: N/A | M9: 596 | N9: Raj Malhotra | O9: 2022 | P9: Below Target
A10: RG-009 | B10: 45544 | C10: Meena Shah | D10: RG Heights | E10: Bopal | F10: 2BHK | G10: 4900000 | H10: 4900000 | I10: Confirmed | J10: 46219 | K10: 7500000 | L10: NRI buyer | M10: 0 | N10: Raj Malhotra | O10: 2022 | P10: Excellent
A11: RG-010 | B11: 45462 | C11: Meena Shah | D11: RG Residency | E11: Adajan | F11: 3BHK | G11: 8650000 | H11: 8650000 | I11: Confirmed | J11: 45999 | K11: 7500000 | L11: Repeat client | M11: 0 | N11: Sneha Kapoor | O11: 2021 | P11: Excellent
A12: RG-011 | B12: 45529 | C12: Amit Verma | D12: RG Residency | E12: Adajan | F12: 2BHK | G12: 5700000 | H12: 0 | I12: Cancelled | J12: 46020 | K12: 9000000 | L12: Referred by agent | M12: 0 | N12: Sneha Kapoor | O12: 2021 | P12: N/A
A13: RG-012 | B13: 45524 | C13: Amit Verma | D13: RG Greens | E13: Vesu | F13: 2BHK | G13: 5250000 | H13: 1800000 | I13: Pending | J13: 46084 | K13: 9000000 | L13: NRI buyer | M13: 587 | N13: Priya Nair | O13: 2023 | P13: Below Target
A14: RG-013 | B14: 45471 | C14: Pooja Desai | D14: RG Heights | E14: Bopal | F14: 3BHK | G14: 8300000 | H14: 8300000 | I14: Confirmed | J14: 46305 | K14: 8500000 | L14: Referred by agent | M14: 0 | N14: Raj Malhotra | O14: 2022 | P14: Excellent
A15: RG-014 | B15: 45428 | C15: Karan Mehta | D15: RG Greens | E15: Vesu | F15: 1BHK | G15: 3300000 | H15: 3300000 | I15: Confirmed | J15: 46197 | K15: 7000000 | L15: N/A | M15: 0 | N15: Priya Nair | O15: 2023 | P15: Excellent
A16: RG-015 | B16: 45365 | C16: Amit Verma | D16: RG Heights | E16: Bopal | F16: 3BHK | G16: 8950000 | H16: 3300000 | I16: Pending | J16: 45953 | K16: 9000000 | L16: Repeat client | M16: 746 | N16: Raj Malhotra | O16: 2022 | P16: Below Target
... A431: RG-430 | B431: 45424 | C431: Meena Shah | D431: RG Residency | E431: Adajan | F431: 2BHK | G431: 4800000 | H431: 1150000 | I431: Pending | J431: 46299 | K431: 7500000 | L431: N/A | M431: 687 | N431: Sneha Kapoor | O431: 2021 | P431: Below Target

Sheet MIS Summary
A1: Project Name | B1: Total Revenue
A2: RG Residency | B2: =SUMIFS('Cleaned Data'!G:G,'Cleaned Data'!D:D,'MIS Summary'!A2) -> 1179650000
A3: RG Heights | B3: =SUMIFS('Cleaned Data'!G:G,'Cleaned Data'!D:D,'MIS Summary'!A3) -> 1277100000
A4: RG Greens | B4: =SUMIFS('Cleaned Data'!G:G,'Cleaned Data'!D:D,'MIS Summary'!A4) -> 387750000
A6: Payment Status | B6: Count
A7: Confirmed | B7: =COUNTIFS('Cleaned Data'!I:I,'MIS Summary'!A7) -> 211
A8: Pending | B8: =COUNTIFS('Cleaned Data'!I:I,'MIS Summary'!A8) -> 157
A9: Cancelled | B9: =COUNTIFS('Cleaned Data'!I:I,'MIS Summary'!A9) -> 62
A11: Flat Type | B11: Total Revenue
A12: 1BHK | B12: =SUMIFS('Cleaned Data'!G:G,'Cleaned Data'!F:F,'MIS Summary'!A12) -> 175750000
A13: 2BHK | B13: =SUMIFS('Cleaned Data'!G:G,'Cleaned Data'!F:F,'MIS Summary'!A13) -> 883500000
A14: 3BHK | B14: =SUMIFS('Cleaned Data'!G:G,'Cleaned Data'!F:F,'MIS Summary'!A14) -> 931450000
A15: 4BHK | B15: =SUMIFS('Cleaned Data'!G:G,'Cleaned Data'!F:F,'MIS Summary'!A15) -> 853800000
A17: Sales Executive | B17: Total Bookings | C17: Total Revenue | D17: Performance Rating
A18: Ravi Patel | B18: =COUNTIFS('Cleaned Data'!C:C,'MIS Summary'!A18) -> 81 | C18: =SUMIFS('Cleaned Data'!G:G,'Cleaned Data'!C:C,'MIS Summary'!A18) -> 488600000 | D18: =IF(Bookings_by_Sales_Executive[[#This Row],[Total Revenue]]/Bookings_by_Sales_Executive[[#This Row],[Total Bookings]]>1000000,"Execllent",IF(Bookings_by_Sales_Executive[[#This Row],[Total Revenue]]/Bookings_by_Sales_Executive[[#This Row],[Total Bookings]]>=800000,"Good","Below Target")) -> Execllent
A19: Meena Shah | B19: =COUNTIFS('Cleaned Data'!C:C,'MIS Summary'!A19) -> 84 | C19: =SUMIFS('Cleaned Data'!G:G,'Cleaned Data'!C:C,'MIS Summary'!A19) -> 595800000 | D19: =IF(Bookings_by_Sales_Executive[[#This Row],[Total Revenue]]/Bookings_by_Sales_Executive[[#This Row],[Total Bookings]]>1000000,"Execllent",IF(Bookings_by_Sales_Executive[[#This Row],[Total Revenue]]/Bookings_by_Sales_Executive[[#This Row],[Total Bookings]]>=800000,"Good","Below Target")) -> Execllent
A20: Amit Verma | B20: =COUNTIFS('Cleaned Data'!C:C,'MIS Summary'!A20) -> 90 | C20: =SUMIFS('Cleaned Data'!G:G,'Cleaned Data'!C:C,'MIS Summary'!A20) -> 563850000 | D20: =IF(Bookings_by_Sales_Executive[[#This Row],[Total Revenue]]/Bookings_by_Sales_Executive[[#This Row],[Total Bookings]]>1000000,"Execllent",IF(Bookings_by_Sales_Executive[[#This Row],[Total Revenue]]/Bookings_by_Sales_Executive[[#This Row],[Total Bookings]]>=800000,"Good","Below Target")) -> Execllent
A21: Pooja Desai | B21: =COUNTIFS('Cleaned Data'!C:C,'MIS Summary'!A21) -> 106 | C21: =SUMIFS('Cleaned Data'!G:G,'Cleaned Data'!C:C,'MIS Summary'!A21) -> 703600000 | D21: =IF(Bookings_by_Sales_Executive[[#This Row],[Total Revenue]]/Bookings_by_Sales_Executive[[#This Row],[Total Bookings]]>1000000,"Execllent",IF(Bookings_by_Sales_Executive[[#This Row],[Total Revenue]]/Bookings_by_Sales_Executive[[#This Row],[Total Bookings]]>=800000,"Good","Below Target")) -> Execllent
A22: Karan Mehta | B22: =COUNTIFS('Cleaned Data'!C:C,'MIS Summary'!A22) -> 69 | C22: =SUMIFS('Cleaned Data'!G:G,'Cleaned Data'!C:C,'MIS Summary'!A22) -> 492650000 | D22: =IF(Bookings_by_Sales_Executive[[#This Row],[Total Revenue]]/Bookings_by_Sales_Executive[[#This Row],[Total Bookings]]>1000000,"Execllent",IF(Bookings_by_Sales_Executive[[#This Row],[Total Revenue]]/Bookings_by_Sales_Executive[[#This Row],[Total Bookings]]>=800000,"Good","Below Target")) -> Execllent

Sheet Annual_MIS
A1: Sales Executive | B1: Annual Target | C1: Annual Revenue | D1: % Achieved | E1: Status
A2: {=_xlfn.UNIQUE('Cleaned Data'!C2:C431)} -> Pooja Desai | B2: 680000000 | C2: =SUMIFS('Cleaned Data'!G:G,'Cleaned Data'!C:C,A2) -> 703600000 | D2: =C2/B2 -> 1.0347059 | E2: =IF(D2>=1,"Excellent",IF(D2>=0.8,"Good","Below Target")) -> Excellent
A3: Ravi Patel | B3: 550000000 | C3: =SUMIFS('Cleaned Data'!G:G,'Cleaned Data'!C:C,A3) -> 488600000 | D3: =C3/B3 -> 0.88836364 | E3: =IF(D3>=1,"Excellent",IF(D3>=0.8,"Good","Below Target")) -> Good
A4: Karan Mehta | B4: 550000000 | C4: =SUMIFS('Cleaned Data'!G:G,'Cleaned Data'!C:C,A4) -> 492650000 | D4: =C4/B4 -> 0.89572727 | E4: =IF(D4>=1,"Excellent",IF(D4>=0.8,"Good","Below Target")) -> Good
A5: Meena Shah | B5: 650000000 | C5: =SUMIFS('Cleaned Data'!G:G,'Cleaned Data'!C:C,A5) -> 595800000 | D5: =C5/B5 -> 0.91661538 | E5: =IF(D5>=1,"Excellent",IF(D5>=0.8,"Good","Below Target")) -> Good
A6: Amit Verma | B6: 620000000 | C6: =SUMIFS('Cleaned Data'!G:G,'Cleaned Data'!C:C,A6) -> 563850000 | D6: =C6/B6 -> 0.90943548 | E6: =IF(D6>=1,"Excellent",IF(D6>=0.8,"Good","Below Target")) -> Good

Sheet Monthly_MIS
A1: Sales Executive | B1: Monthly Target | C1: Revenue This Month | D1: % Achieved | E1: Status
A2: Pooja Desai | B2: 55000000 | C2: =SUMIFS('Cleaned Data'!G:G,'Cleaned Data'!C:C,A2,'Cleaned Data'!B:B,">="&DATE(2024,12,1),'Cleaned Data'!B:B,"<="&DATE(2024,12,31)) -> 47000000 | D2: =C2/B2 -> 0.85454545 | E2: =IF(D2>=1,"Excellent",IF(D2>=0.8,"Good","Below Target")) -> Good
A3: Ravi Patel | B3: 45000000 | C3: =SUMIFS('Cleaned Data'!G:G,'Cleaned Data'!C:C,A3,'Cleaned Data'!B:B,">="&DATE(2024,12,1),'Cleaned Data'!B:B,"<="&DATE(2024,12,31)) -> 41700000 | D3: =C3/B3 -> 0.92666667 | E3: =IF(D3>=1,"Excellent",IF(D3>=0.8,"Good","Below Target")) -> Good
A4: Karan Mehta | B4: 35000000 | C4: =SUMIFS('Cleaned Data'!G:G,'Cleaned Data'!C:C,A4,'Cleaned Data'!B:B,">="&DATE(2024,12,1),'Cleaned Data'!B:B,"<="&DATE(2024,12,31)) -> 33350000 | D4: =C4/B4 -> 0.95285714 | E4: =IF(D4>=1,"Excellent",IF(D4>=0.8,"Good","Below Target")) -> Good
A5: Meena Shah | B5: 50000000 | C5: =SUMIFS('Cleaned Data'!G:G,'Cleaned Data'!C:C,A5,'Cleaned Data'!B:B,">="&DATE(2024,12,1),'Cleaned Data'!B:B,"<="&DATE(2024,12,31)) -> 91000000 | D5: =C5/B5 -> 1.82 | E5: =IF(D5>=1,"Excellent",IF(D5>=0.8,"Good","Below Target")) -> Excellent
A6: Amit Verma | B6: 30000000 | C6: =SUMIFS('Cleaned Data'!G:G,'Cleaned Data'!C:C,A6,'Cleaned Data'!B:B,">="&DATE(2024,12,1),'Cleaned Data'!B:B,"<="&DATE(2024,12,31)) -> 26450000 | D6: =C6/B6 -> 0.88166667 | E6: =IF(D6>=1,"Excellent",IF(D6>=0.8,"Good","Below Target")) -> Good

Sheet Daily_MIS
A1: Sales Executive | B1: Daily Target | C1: Today's Revenue | D1: % Achieved | E1: Status
A2: Pooja Desai | B2: 55000000 | C2: =SUMIFS('Cleaned Data'!G:G,'Cleaned Data'!C:C,A2,'Cleaned Data'!B:B,TODAY()) -> 0 | D2: =C2/B2 -> 0 | E2: =IF(D2>=1,"Excellent",IF(D2>=0.8,"Good","Below Target")) -> Below Target
A3: Ravi Patel | B3: 45000000 | C3: =SUMIFS('Cleaned Data'!G:G,'Cleaned Data'!C:C,A3,'Cleaned Data'!B:B,TODAY()) -> 0 | D3: =C3/B3 -> 0 | E3: =IF(D3>=1,"Excellent",IF(D3>=0.8,"Good","Below Target")) -> Below Target
A4: Karan Mehta | B4: 35000000 | C4: =SUMIFS('Cleaned Data'!G:G,'Cleaned Data'!C:C,A4,'Cleaned Data'!B:B,TODAY()) -> 0 | D4: =C4/B4 -> 0 | E4: =IF(D4>=1,"Excellent",IF(D4>=0.8,"Good","Below Target")) -> Below Target
A5: Meena Shah | B5: 50000000 | C5: =SUMIFS('Cleaned Data'!G:G,'Cleaned Data'!C:C,A5,'Cleaned Data'!B:B,TODAY()) -> 0 | D5: =C5/B5 -> 0 | E5: =IF(D5>=1,"Excellent",IF(D5>=0.8,"Good","Below Target")) -> Below Target
A6: Amit Verma | B6: 30000000 | C6: =SUMIFS('Cleaned Data'!G:G,'Cleaned Data'!C:C,A6,'Cleaned Data'!B:B,TODAY()) -> 0 | D6: =C6/B6 -> 0 | E6: =IF(D6>=1,"Excellent",IF(D6>=0.8,"Good","Below Target")) -> Below Target

Sheet AutomateCleaning
A1: Booking_ID | B1: Booking_Date | C1: Sales_Executive | D1: Project_Name | E1: Location | F1: Flat_Type | G1: Booking_Amount | H1: Amount_Received | I1: Payment_Status | J1: Possession_Date | K1: Sales_Target | L1: Remarks
A2: RG-001 | B2: 45575 | C2: Pooja Desai | D2: RG Residency | E2: Adajan | F2: 2BHK | G2: 5900000 | H2: 0 | I2: Cancelled | J2: 46082 | K2: 8500000 | L2: Builder referral
A3: RG-002 | B3: 45508 | C3: Pooja Desai | D3: RG Residency | E3: Adajan | F3: 2BHK | G3: 4200000 | H3: 4200000 | I3: Confirmed | J3: 45768 | K3: 8500000 | L3: N\A
A4: RG-003 | B4: 45387 | C4: Ravi Patel | D4: RG Heights | E4: Bopal | F4: 1BHK | G4: 3500000 | H4: 900000 | I4: Pending | J4: 46086 | K4: 8000000 | L4: N\A
A5: RG-004 | B5: 45302 | C5: Karan Mehta | D5: RG Residency | E5: Adajan | F5: 2BHK | G5: 5400000 | H5: 5400000 | I5: Confirmed | J5: 46059 | K5: 7000000 | L5: Online inquiry
A6: RG-005 | B6: 45555 | C6: Meena Shah | D6: RG Heights | E6: Bopal | F6: 2BHK | G6: 5150000 | H6: 5150000 | I6: Confirmed | J6: 46319 | K6: 7500000 | L6: N\A
A7: RG-006 | B7: 45485 | C7: Pooja Desai | D7: RG Residency | E7: Adajan | F7: 3BHK | G7: 7950000 | H7: 7950000 | I7: Confirmed | J7: 45847 | K7: 8500000 | L7: N\A
A8: RG-007 | B8: 45519 | C8: Amit Verma | D8: RG Residency | E8: Adajan | F8: 2BHK | G8: 4200000 | H8: 4200000 | I8: Confirmed | J8: 46140 | K8: 9000000 | L8: N\A
A9: RG-008 | B9: 45515 | C9: Pooja Desai | D9: RG Heights | E9: Bopal | F9: 2BHK | G9: 4400000 | H9: 1350000 | I9: Pending | J9: 46071 | K9: 8500000 | L9: N\A
A10: RG-009 | B10: 45544 | C10: Meena Shah | D10: RG Heights | E10: Bopal | F10: 2BHK | G10: 4900000 | H10: 4900000 | I10: Confirmed | J10: 46219 | K10: 7500000 | L10: NRI buyer
A11: RG-010 | B11: 45462 | C11: Meena Shah | D11: RG Residency | E11: Adajan | F11: 3BHK | G11: 8650000 | H11: 8650000 | I11: Confirmed | J11: 45999 | K11: 7500000 | L11: Repeat client
A12: RG-011 | B12: 45529 | C12: Amit Verma | D12: RG Residency | E12: Adajan | F12: 2BHK | G12: 5700000 | H12: 0 | I12: Cancelled | J12: 46020 | K12: 9000000 | L12: Referred by agent
A13: RG-012 | B13: 45524 | C13: Amit Verma | D13: RG Greens | E13: Vesu | F13: 2BHK | G13: 5250000 | H13: 1800000 | I13: Pending | J13: 46084 | K13: 9000000 | L13: NRI buyer
... A431: RG-430 | B431: 45424 | C431: Meena Shah | D431: RG Residency | E431: Adajan | F431: 2BHK | G431: 4800000 | H431: 1150000 | I431: Pending | J431: 46299 | K431: 7500000 | L431: N\A

Sheet Raw Data
A1: Booking_ID | B1: Booking_Date | C1: Sales_Executive | D1: Project_Name | E1: Location | F1: Flat_Type | G1: Booking_Amount | H1: Amount_Received | I1: Payment_Status | J1: Possession_Date | K1: Sales_Target | L1: Remarks
A2: RG-001 | B2: 45575 | C2: Pooja Desai | D2: RG Residency | E2: Adajan | F2: 2BHK | G2: 5900000 | H2: 0 | I2: Cancelled | J2: 46082 | K2: 8500000 | L2: Builder referral
A3: RG-002 | B3: 45508 | C3: Pooja Desai | D3: RG Residency | E3: Adajan | F3: 2BHK | G3: 4200000 | H3: 4200000 | I3: Confirmed | J3: 45768 | K3: 8500000
A4: RG-003 | B4: 45387 | C4: Ravi Patel | D4: RG Heights | E4: Bopal | F4: 1BHK | G4: 3500000 | H4: 900000 | I4: Pending | J4: 46086 | K4: 8000000
A5: RG-004 | B5: 45302 | C5: Karan Mehta | D5: RG Residency | E5: Adajan | F5: 2BHK | G5: 5400000 | H5: 5400000 | I5: Confirmed | J5: 46059 | K5: 7000000 | L5: Online inquiry
A6: RG-005 | B6: 45555 | C6: Meena Shah | D6: RG Heights | E6: Bopal | F6: 2BHK | G6: 5150000 | H6: 5150000 | I6: Confirmed | J6: 46319 | K6: 7500000
A7: RG-006 | B7: 45485 | C7: Pooja Desai | D7: RG Residency | E7: Adajan | F7: 3BHK | G7: 7950000 | H7: 7950000 | I7: Confirmed | J7: 45847 | K7: 8500000
A8: RG-007 | B8: 45519 | C8: Amit Verma | D8: RG Residency | E8: Adajan | F8: 2BHK | G8: 4200000 | H8: 4200000 | I8: Confirmed | J8: 46140 | K8: 9000000
A9: RG-008 | B9: 45515 | C9: Pooja Desai | D9: RG Heights | E9: Bopal | F9: 2BHK | G9: 4400000 | H9: 1350000 | I9: Pending | J9: 46071 | K9: 8500000
A10: RG-009 | B10: 45544 | C10: Meena Shah | D10: RG Heights | E10: Bopal | F10: 2BHK | G10: 4900000 | H10: 4900000 | I10: Confirmed | J10: 46219 | K10: 7500000 | L10: NRI buyer
A11: RG-010 | B11: 45462 | C11: Meena Shah | D11: RG Residency | E11: Adajan | F11: 3BHK | G11: 8650000 | H11: 8650000 | I11: Confirmed | J11: 45999 | K11: 7500000 | L11: Repeat client
A12: RG-011 | B12: 45529 | C12: Amit Verma | D12: RG Residency | E12: Adajan | F12: 2BHK | G12: 5700000 | H12: 0 | I12: Cancelled | J12: 46020 | K12: 9000000 | L12: Referred by agent
A13: RG-012 | B13: 45524 | C13: Amit Verma | D13: RG Greens | E13: Vesu | F13: 2BHK | G13: 5250000 | H13: 1800000 | I13: Pending | J13: 46084 | K13: 9000000 | L13: NRI buyer
A14: RG-013 | B14: 45471 | C14: Pooja Desai | D14: RG Heights | E14: Bopal | F14: 3BHK | G14: 8300000 | H14: 8300000 | I14: Confirmed | J14: 46305 | K14: 8500000 | L14: Referred by agent
A15: RG-014 | B15: 45428 | C15: Karan Mehta | D15: RG Greens | E15: Vesu | F15: 1BHK | G15: 3300000 | H15: 3300000 | I15: Confirmed | J15: 46197 | K15: 7000000
A16: RG-015 | B16: 45365 | C16: Amit Verma | D16: RG Heights | E16: Bopal | F16: 3BHK | G16: 8950000 | H16: 3300000 | I16: Pending | J16: 45953 | K16: 9000000 | L16: Repeat client
A17: RG-016 | B17: 45574 | C17: Pooja Desai | D17: RG Heights | E17: Bopal | F17: 3BHK | G17: 7700000 | H17: 7700000 | I17: Confirmed | J17: 46268 | K17: 8500000
A18: RG-017 | B18: 45568 | C18: Karan Mehta | D18: RG Heights | E18: Bopal | F18: 4BHK | G18: 10600000 | H18: 2250000 | I18: Pending | J18: 45914 | K18: 7000000 | L18: Walk-in customer
A19: RG-018 | B19: 45313 | C19: Pooja Desai | D19: RG Heights | E19: Bopal | F19: 1BHK | G19: 3250000 | H19: 0 | I19: Cancelled | J19: 45746 | K19: 8500000 | L19: Builder referral
A20: RG-019 | B20: 45522 | C20: Karan Mehta | D20: RG Residency | E20: Adajan | F20: 2BHK | G20: 4600000 | H20: 0 | I20: Cancelled | J20: 45991 | K20: 7000000
A21: RG-020 | B21: 45427 | C21: Pooja Desai | D21: RG Heights | E21: Bopal | F21: 2BHK | G21: 4650000 | H21: 4650000 | I21: Confirmed | J21: 45616 | K21: 8500000
A22: RG-021 | B22: 45596 | C22: RAVI PATEL | D22: RG Residency | E22: Adajan | F22: 3BHK | G22: 8000000 | H22: 8000000 | I22: Confirmed | J22: 46438 | K22: 8000000 | L22: Referred by agent
A23: RG-022 | B23: 45331 | C23: Karan Mehta | D23: RG Residency | E23: Adajan | F23: 2BHK | G23: 4450000 | H23: 1750000 | I23: Pending | J23: 45921 | K23: 7000000 | L23: NRI buyer
A24: RG-023 | B24: 45532 | C24: Pooja Desai | D24: RG Residency | E24: Adajan | F24: 1BHK | G24: 2750000 | H24: 350000 | I24: Pending | J24: 45778 | K24: 8500000
A25: RG-024 | B25: 45378 | C25: Amit Verma | D25: RG Heights | E25: Bopal | F25: 2BHK | G25: 5200000 | H25: 5200000 | I25: Confirmed | J25: 46084 | K25: 9000000 | L25: NRI buyer
A26: RG-025 | B26: 45619 | C26: Ravi Patel | D26: RG Heights | E26: Bopal | F26: 2BHK | G26: 4450000 | H26: 4450000 | I26: Confirmed | J26: 45903 | K26: 8000000
A27: RG-026 | B27: 45550 | C27: Pooja Desai | D27: RG Heights | E27: Bopal | F27: 4BHK | G27: 10500000 | H27: 10500000 | I27: Confirmed | J27: 45829 | K27: 8500000
A28: RG-027 | B28: 45296 | C28: Ravi Patel | D28: RG Residency | E28: Adajan | F28: 3BHK | G28: 6650000 | H28: 6650000 | I28: Confirmed | J28: 46072 | K28: 8000000
A29: RG-028 | B29: 45572 | C29: KARAN MEHTA | D29: RG Heights | E29: Bopal | F29: 4BHK | G29: 12400000 | H29: 0 | I29: Cancelled | J29: 45801 | K29: 7000000 | L29: Referred by agent
A30: RG-029 | B30: 45496 | C30: Meena Shah | D30: RG Greens | E30: Vesu | F30: 3BHK | G30: 6950000 | H30: 6950000 | I30: Confirmed | J30: 45923 | K30: 7500000
A31: RG-030 | B31: 45394 | C31: Ravi Patel | D31: RG Residency | E31: Adajan | F31: 3BHK | G31: 7700000 | H31: 7700000 | I31: Confirmed | J31: 46058 | K31: 8000000 | L31: NRI buyer
A32: RG-031 | B32: 45305 | C32: Karan Mehta | D32: RG Greens | E32: Vesu | F32: 2BHK | G32: 4050000 | H32: 4050000 | I32: Confirmed | J32: 45764 | K32: 7000000 | L32: Builder referral
A33: RG-032 | B33: 45655 | C33: Meena Shah | D33: RG Residency | E33: Adajan | F33: 3BHK | G33: 8200000 | H33: 8200000 | I33: Confirmed | J33: 46065 | K33: 7500000 | L33: NRI buyer
A34: RG-033 | B34: 45479 | C34: RAVI PATEL | D34: RG Residency | E34: Adajan | F34: 2BHK | G34: 5150000 | H34: 5150000 | I34: Confirmed | J34: 45734 | K34: 8000000
A35: RG-034 | B35: 45445 | C35: Meena Shah | D35: RG Heights | E35: Bopal | F35: 3BHK | G35: 8750000 | H35: 8750000 | I35: Confirmed | J35: 46018 | K35: 7500000 | L35: Walk-in customer
A36: RG-035 | B36: 45472 | C36: Ravi Patel | D36: RG Residency | E36: Adajan | F36: 2BHK | G36: 5400000 | H36: 900000 | I36: Pending | J36: 45762 | K36: 8000000 | L36: Repeat client
A37: RG-036 | B37: 45522 | C37: Amit Verma | D37: RG Residency | E37: Adajan | F37: 1BHK | G37: 2800000 | H37: 850000 | I37: Pending | J37: 46319 | K37: 9000000 | L37: Referred by agent
A38: RG-037 | B38: 45502 | C38: Amit Verma | D38: RG Heights | E38: Bopal | F38: 4BHK | G38: 9950000 | H38: 9950000 | I38: Confirmed | J38: 46296 | K38: 9000000 | L38: Builder referral
A39: RG-038 | B39: 45409 | C39: Pooja Desai | D39: RG Residency | E39: Adajan | F39: 1BHK | G39: 2850000 | H39: 2850000 | I39: Confirmed | J39: 45895 | K39: 8500000 | L39: Walk-in customer
A40: RG-039 | B40: 45518 | C40: Pooja Desai | D40: RG Heights | E40: Bopal | F40: 2BHK | G40: 4550000 | H40: 4550000 | I40: Confirmed | J40: 46222 | K40: 8500000 | L40: NRI buyer
...
